Workbook

Sheet Cover
A1: Headcount & Operating Expense Planning Model — FY2027
A2: Built by Taruni Komma | Brightwater Analytics, Inc. (simulated ~70-person software company) | Monthly budget, Jan–Dec 2027
A4: KEY OUTPUTS (live, selected scenario)
A5: Scenario | B5: =Assumptions!C5 -> Plan
A6: Total FY2027 operating expense | B6: =Summary!B15 -> 15400173
A7: Over / (under) leadership ceiling | B7: =Summary!B17 -> 400172.93
A8: Opex as % of revenue | B8: =Summary!B19 -> 0.78975246
A9: Headcount: Jan 1 → Dec 31 | B9: =TEXT(Summary!F11,"0")&" → "&TEXT(Summary!G11,"0") -> 60 → 71
A10: New hires in plan | B10: =Summary!B24 -> 14
A11: People costs as % of opex | B11: =Summary!B23 -> 0.69249047
A12: Department budgets tie to total? | B12: =IF('Department Budget'!N96=0,"Yes","No — check") -> Yes
A14: HOW THE WORKBOOK IS ORGANIZED
A15: • Assumptions — scenario selector (B5), compensation rates, per-head costs, department drivers, targets
A16: • Roster — 60 employees and 18 open roles with salary, dates, and hiring priority
A17: • Headcount Calc — prorated FTE and salary for every person, every month (merit and departures included)
A18: • Department Budget — monthly budget by department and line item, rolled up to company total
A19: • Summary — FY2027 budget vs. FY2026 actual and the leadership ceiling, with a department chart
A20: • Scenarios — Plan, Hiring freeze, Accelerated growth and Deferred hiring side by side
A22: COLOR LEGEND
A23: Blue text — input
A24: Black text — formula
A25: Green text — link to another sheet
A26: Yellow fill — key lever

Sheet Assumptions
A1: Planning Assumptions — FY2027 (January–December 2027)
A2: Brightwater Analytics, Inc. is a simulated software company; all data is illustrative. Blue = input, yellow = key lever.
A4: SCENARIO
A5: Scenario selector (1 = Plan, 2 = Hiring freeze, 3 = Accelerated growth, 4 = Deferred hiring) | B5: 1 | C5: =CHOOSE($B$5,"Plan","Hiring freeze","Accelerated growth","Deferred hiring") -> Plan
A7: Lever | B7: Plan | C7: Hiring freeze | D7: Accelerated | E7: Deferred hiring | F7: Live
A8: Open roles approved (include priority ≤) | B8: 2 | C8: 1 | D8: 3 | E8: 2 | F8: =INDEX(B8:E8,Assumptions!$B$5) -> 2
A9: All hire start dates pulled forward (months) | B9: 0 | C9: 0 | D9: 1 | E9: 0 | F9: =INDEX(B9:E9,Assumptions!$B$5) -> 0
A10: Priority 2 hire start dates delayed (months) | B10: 0 | C10: 0 | D10: 0 | E10: 3 | F10: =INDEX(B10:E10,Assumptions!$B$5) -> 0
A11: Change to programs & vendor spend | B11: 0 | C11: -0.15 | D11: 0.1 | E11: -0.05 | F11: =INDEX(B11:E11,Assumptions!$B$5) -> 0
A12: Priority 1 = critical/backfill, 2 = planned growth, 3 = stretch. Freeze keeps only priority 1 roles.
A13: COMPENSATION & PER-HEAD COSTS
A14: Fiscal year start | B14: 46388
A15: Employer payroll taxes (% of salary) | B15: 0.072 | C15: Blended FICA, FUTA and state unemployment
A16: Benefits ($ per FTE per month) | B16: 1150 | C16: Medical, dental, 401(k) match
A17: Annual merit increase (existing employees) | B17: 0.035
A18: Merit effective date | B18: 46478
A19: Recruiting cost (% of new hire salary) | B19: 0.15 | C19: Agency and job-board costs
A20: Laptop and onboarding ($ per hire) | B20: 3000
A21: Software and tools ($ per FTE per month) | B21: 250
A22: Facilities allocation ($ per FTE per month) | B22: 600
A23: Sales on-target variable compensation (% of salary) | B23: 0.3 | C23: Replaces the level bonus for Sales
A25: BONUS TARGET BY LEVEL (% of salary)
A26: Level | B26: Bonus %
A27: 1 | B27: 0.05
A28: 2 | B28: 0.08
A29: 3 | B29: 0.1
A30: 4 | B30: 0.15
A31: 5 | B31: 0.2
A33: DEPARTMENT COST DRIVERS
A34: Department | B34: Travel & entertainment ($/FTE/mo) | C34: Programs & vendors (annual $) | D34: Programs include
A35: Engineering | B35: 150 | C35: 600000 | D35: Dev tools, cloud test environments, contractors
A36: Product | B36: 200 | C36: 100000 | D36: User research, design tools
A37: Sales | B37: 1200 | C37: 300000 | D37: CRM seats, sales events, data providers
A38: Marketing | B38: 400 | C38: 1400000 | D38: Paid media, events, content agencies
A39: Customer Success | B39: 200 | C39: 150000 | D39: Support platform, training
A40: G&A | B40: 150 | C40: 900000 | D40: Audit, legal, insurance, HR systems
A42: COMPANY TARGETS
A43: FY2027 revenue plan ($) | B43: 19500000 | C43: Board-approved plan
A44: FY2026 revenue actual ($) | B44: 15000000
A45: Leadership operating expense ceiling ($) | B45: 15000000 | C45: Maximum FY2027 opex approved by leadership

Sheet Roster
A1: Employee Roster and Hiring Plan
A2: 60 current employees and 18 open roles. Edit salaries, dates or priorities here (blue); the model updates automatically. Simulated data — employee IDs only.
A5: Employee ID | B5: Department | C5: Title | D5: Level | E5: Status | F5: Annual salary ($) | G5: Start date | H5: End date | I5: Priority | J5: Note
A6: ENG-101 | B6: Engineering | C6: Software Engineer I | D6: 1 | E6: Existing | F6: 84500 | G6: 44713
A7: ENG-102 | B7: Engineering | C7: Software Engineer I | D7: 1 | E7: Existing | F7: 81000 | G7: 45962
A8: ENG-103 | B8: Engineering | C8: Software Engineer I | D8: 1 | E8: Existing | F8: 86000 | G8: 43922
A9: ENG-104 | B9: Engineering | C9: Software Engineer I | D9: 1 | E9: Existing | F9: 79500 | G9: 45170
A10: ENG-105 | B10: Engineering | C10: Software Engineer II | D10: 2 | E10: Existing | F10: 110500 | G10: 46054
A11: ENG-106 | B11: Engineering | C11: Software Engineer II | D11: 2 | E11: Existing | F11: 108000 | G11: 44378
A12: ENG-107 | B12: Engineering | C12: Software Engineer II | D12: 2 | E12: Existing | F12: 112500 | G12: 45627
A13: ENG-108 | B13: Engineering | C13: Software Engineer II | D13: 2 | E13: Existing | F13: 109000 | G13: 43586
A14: ENG-109 | B14: Engineering | C14: Software Engineer II | D14: 2 | E14: Existing | F14: 111500 | G14: 44835
A15: ENG-110 | B15: Engineering | C15: Software Engineer II | D15: 2 | E15: Existing | F15: 107000 | G15: 45717
A16: ENG-111 | B16: Engineering | C16: Senior Software Engineer | D16: 3 | E16: Existing | F16: 153000 | G16: 44044 | H16: 46507 | J16: Departing — backfill planned
A17: ENG-112 | B17: Engineering | C17: Senior Software Engineer | D17: 3 | E17: Existing | F17: 141500 | G17: 44927
A18: ENG-113 | B18: Engineering | C18: Senior Software Engineer | D18: 3 | E18: Existing | F18: 148500 | G18: 46174
A19: ENG-114 | B19: Engineering | C19: Senior Software Engineer | D19: 3 | E19: Existing | F19: 145500 | G19: 44501
A20: ENG-115 | B20: Engineering | C20: Senior Software Engineer | D20: 3 | E20: Existing | F20: 151500 | G20: 45383
A21: ENG-116 | B21: Engineering | C21: Senior Software Engineer | D21: 3 | E21: Existing | F21: 147000 | G21: 43709
A22: ENG-117 | B22: Engineering | C22: Staff Engineer | D22: 4 | E22: Existing | F22: 193500 | G22: 44593
A23: ENG-118 | B23: Engineering | C23: Staff Engineer | D23: 4 | E23: Existing | F23: 186000 | G23: 45839
A24: ENG-119 | B24: Engineering | C24: Staff Engineer | D24: 4 | E24: Existing | F24: 197500 | G24: 44166
A25: ENG-120 | B25: Engineering | C25: Director of Engineering | D25: 5 | E25: Existing | F25: 243000 | G25: 45047
A26: PRD-101 | B26: Product | C26: Product Manager | D26: 2 | E26: Existing | F26: 100500 | G26: 45809
A27: PRD-102 | B27: Product | C27: Product Manager | D27: 2 | E27: Existing | F27: 105500 | G27: 44136
A28: PRD-103 | B28: Product | C28: Senior Product Manager | D28: 3 | E28: Existing | F28: 139500 | G28: 45017
... A35: SLS-105 | B35: Sales | C35: Account Executive | D35: 2 | E35: Existing | F35: 84000 | G35: 45323
A36: SLS-106 | B36: Sales | C36: Account Executive | D36: 2 | E36: Existing | F36: 77500 | G36: 43647 | H36: 46568 | J36: Departing — backfill planned
A37: SLS-107 | B37: Sales | C37: Account Executive | D37: 2 | E37: Existing | F37: 81500 | G37: 44896
A38: SLS-108 | B38: Sales | C38: Account Executive | D38: 2 | E38: Existing | F38: 80000 | G38: 45778
A39: SLS-109 | B39: Sales | C39: Senior Account Executive | D39: 3 | E39: Existing | F39: 112000 | G39: 44105
A40: SLS-110 | B40: Sales | C40: Senior Account Executive | D40: 3 | E40: Existing | F40: 109000 | G40: 44986
A41: SLS-111 | B41: Sales | C41: Sales Manager | D41: 4 | E41: Existing | F41: 143000 | G41: 46235
A42: SLS-112 | B42: Sales | C42: VP, Sales | D42: 5 | E42: Existing | F42: 183500 | G42: 44197
A43: MKT-101 | B43: Marketing | C43: Marketing Coordinator | D43: 1 | E43: Existing | F43: 67000 | G43: 45078
A44: MKT-102 | B44: Marketing | C44: Marketing Coordinator | D44: 1 | E44: Existing | F44: 71000 | G44: 46327
A45: MKT-103 | B45: Marketing | C45: Marketing Manager | D45: 2 | E45: Existing | F45: 86500 | G45: 44287
A46: MKT-104 | B46: Marketing | C46: Marketing Manager | D46: 2 | E46: Existing | F46: 91000 | G46: 45536
A47: MKT-105 | B47: Marketing | C47: Director of Marketing | D47: 4 | E47: Existing | F47: 155000 | G47: 43497
A48: MKT-106 | B48: Marketing | C48: VP, Marketing | D48: 5 | E48: Existing | F48: 215500 | G48: 44743
...

Sheet Headcount Calc
A1: Monthly FTE and Salary Engine
A2: FTE is prorated by days employed in each month. Salaries include the merit increase from its effective date for employees hired before the fiscal year.
K3: FTE by month | W3: Salary cost by month ($)
A5: Employee ID | B5: Department | C5: Status | D5: Level | E5: Annual salary | F5: Scenario start | G5: End date | H5: In plan (1/0) | I5: Bonus % | J5: Merit eligible | K5: =DATE(YEAR(Assumptions!$B$14),MONTH(Assumptions!$B$14)+0,1) -> 46388 | L5: =DATE(YEAR(Assumptions!$B$14),MONTH(Assumptions!$B$14)+1,1) -> 46419 | M5: =DATE(YEAR(Assumptions!$B$14),MONTH(Assumptions!$B$14)+2,1) -> 46447 | N5: =DATE(YEAR(Assumptions!$B$14),MONTH(Assumptions!$B$14)+3,1) -> 46478 | O5: =DATE(YEAR(Assumptions!$B$14),MONTH(Assumptions!$B$14)+4,1) -> 46508 | P5: =DATE(YEAR(Assumptions!$B$14),MONTH(Assumptions!$B$14)+5,1) -> 46539 | Q5: =DATE(YEAR(Assumptions!$B$14),MONTH(Assumptions!$B$14)+6,1) -> 46569 | R5: =DATE(YEAR(Assumptions!$B$14),MONTH(Assumptions!$B$14)+7,1) -> 46600 | S5: =DATE(YEAR(Assumptions!$B$14),MONTH(Assumptions!$B$14)+8,1) -> 46631 | T5: =DATE(YEAR(Assumptions!$B$14),MONTH(Assumptions!$B$14)+9,1) -> 46661 | U5: =DATE(YEAR(Assumptions!$B$14),MONTH(Assumptions!$B$14)+10,1) -> 46692 | V5: =DATE(YEAR(Assumptions!$B$14),MONTH(Assumptions!$B$14)+11,1) -> 46722 | W5: =DATE(YEAR(Assumptions!$B$14),MONTH(Assumptions!$B$14)+0,1) -> 46388 | X5: =DATE(YEAR(Assumptions!$B$14),MONTH(Assumptions!$B$14)+1,1) -> 46419 | Y5: =DATE(YEAR(Assumptions!$B$14),MONTH(Assumptions!$B$14)+2,1) -> 46447 | Z5: =DATE(YEAR(Assumptions!$B$14),MONTH(Assumptions!$B$14)+3,1) -> 46478 | AA5: =DATE(YEAR(Assumptions!$B$14),MONTH(Assumptions!$B$14)+4,1) -> 46508 | AB5: =DATE(YEAR(Assumptions!$B$14),MONTH(Assumptions!$B$14)+5,1) -> 46539 | AC5: =DATE(YEAR(Assumptions!$B$14),MONTH(Assumptions!$B$14)+6,1) -> 46569 | AD5: =DATE(YEAR(Assumptions!$B$14),MONTH(Assumptions!$B$14)+7,1) -> 46600 | AE5: =DATE(YEAR(Assumptions!$B$14),MONTH(Assumptions!$B$14)+8,1) -> 46631 | AF5: =DATE(YEAR(Assumptions!$B$14),MONTH(Assumptions!$B$14)+9,1) -> 46661 | AG5: =DATE(YEAR(Assumptions!$B$14),MONTH(Assumptions!$B$14)+10,1) -> 46692 | AH5: =DATE(YEAR(Assumptions!$B$14),MONTH(Assumptions!$B$14)+11,1) -> 46722
A6: =Roster!A6 -> ENG-101 | B6: =Roster!B6 -> Engineering | C6: =Roster!E6 -> Existing | D6: =Roster!D6 -> 1 | E6: =Roster!F6 -> 84500 | F6: =IF(Roster!E6="Open role",MAX(Assumptions!$B$14,EDATE(Roster!G6,IF(Roster!I6=2,Assumptions!$F$10,0)-Assumptions!$F$9)),Roster!G6) -> 44713 | G6: =IF(Roster!H6="",DATE(2099,12,31),Roster!H6) -> 73050 | H6: =IF(Roster!E6="Existing",1,IF(Roster!I6<=Assumptions!$F$8,1,0)) -> 1 | I6: =IF(B6="Sales",Assumptions!$B$23,VLOOKUP(D6,Assumptions!$A$27:$B$31,2,FALSE())) -> 0.05 | J6: =IF(F6<Assumptions!$B$14,1,0) -> 1 | K6: =IF($H6=1,MAX(0,MIN($G6,EOMONTH(K$5,0))-MAX($F6,K$5)+1)/DAY(EOMONTH(K$5,0)),0) -> 1 | L6: =IF($H6=1,MAX(0,MIN($G6,EOMONTH(L$5,0))-MAX($F6,L$5)+1)/DAY(EOMONTH(L$5,0)),0) -> 1 | M6: =IF($H6=1,MAX(0,MIN($G6,EOMONTH(M$5,0))-MAX($F6,M$5)+1)/DAY(EOMONTH(M$5,0)),0) -> 1 | N6: =IF($H6=1,MAX(0,MIN($G6,EOMONTH(N$5,0))-MAX($F6,N$5)+1)/DAY(EOMONTH(N$5,0)),0) -> 1 | O6: =IF($H6=1,MAX(0,MIN($G6,EOMONTH(O$5,0))-MAX($F6,O$5)+1)/DAY(EOMONTH(O$5,0)),0) -> 1 | P6: =IF($H6=1,MAX(0,MIN($G6,EOMONTH(P$5,0))-MAX($F6,P$5)+1)/DAY(EOMONTH(P$5,0)),0) -> 1 | Q6: =IF($H6=1,MAX(0,MIN($G6,EOMONTH(Q$5,0))-MAX($F6,Q$5)+1)/DAY(EOMONTH(Q$5,0)),0) -> 1 | R6: =IF($H6=1,MAX(0,MIN($G6,EOMONTH(R$5,0))-MAX($F6,R$5)+1)/DAY(EOMONTH(R$5,0)),0) -> 1 | ... V6: =IF($H6=1,MAX(0,MIN($G6,EOMONTH(V$5,0))-MAX($F6,V$5)+1)/DAY(EOMONTH(V$5,0)),0) -> 1 | W6: =$E6/12*K6*IF(AND($J6=1,W$5>=Assumptions!$B$18),1+Assumptions!$B$17,1) -> 7041.6667 | X6: =$E6/12*L6*IF(AND($J6=1,X$5>=Assumptions!$B$18),1+Assumptions!$B$17,1) -> 7041.6667 | Y6: =$E6/12*M6*IF(AND($J6=1,Y$5>=Assumptions!$B$18),1+Assumptions!$B$17,1) -> 7041.6667 | Z6: =$E6/12*N6*IF(AND($J6=1,Z$5>=Assumptions!$B$18),1+Assumptions!$B$17,1) -> 7288.125 | AA6: =$E6/12*O6*IF(AND($J6=1,AA$5>=Assumptions!$B$18),1+Assumptions!$B$17,1) -> 7288.125 | AB6: =$E6/12*P6*IF(AND($J6=1,AB$5>=Assumptions!$B$18),1+Assumptions!$B$17,1) -> 7288.125 | AC6: =$E6/12*Q6*IF(AND($J6=1,AC$5>=Assumptions!$B$18),1+Assumptions!$B$17,1) -> 7288.125 | AD6: =$E6/12*R6*IF(AND($J6=1,AD$5>=Assumptions!$B$18),1+Assumptions!$B$17,1) -> 7288.125 | ... AH6: =$E6/12*V6*IF(AND($J6=1,AH$5>=Assumptions!$B$18),1+Assumptions!$B$17,1) -> 7288.125
A7: =Roster!A7 -> ENG-102 | B7: =Roster!B7 -> Engineering | C7: =Roster!E7 -> Existing | D7: =Roster!D7 -> 1 | E7: =Roster!F7 -> 81000 | F7: =IF(Roster!E7="Open role",MAX(Assumptions!$B$14,EDATE(Roster!G7,IF(Roster!I7=2,Assumptions!$F$10,0)-Assumptions!$F$9)),Roster!G7) -> 45962 | G7: =IF(Roster!H7="",DATE(2099,12,31),Roster!H7) -> 73050 | H7: =IF(Roster!E7="Existing",1,IF(Roster!I7<=Assumptions!$F$8,1,0)) -> 1 | I7: =IF(B7="Sales",Assumptions!$B$23,VLOOKUP(D7,Assumptions!$A$27:$B$31,2,FALSE())) -> 0.05 | J7: =IF(F7<Assumptions!$B$14,1,0) -> 1 | K7: =IF($H7=1,MAX(0,MIN($G7,EOMONTH(K$5,0))-MAX($F7,K$5)+1)/DAY(EOMONTH(K$5,0)),0) -> 1 | L7: =IF($H7=1,MAX(0,MIN($G7,EOMONTH(L$5,0))-MAX($F7,L$5)+1)/DAY(EOMONTH(L$5,0)),0) -> 1 | M7: =IF($H7=1,MAX(0,MIN($G7,EOMONTH(M$5,0))-MAX($F7,M$5)+1)/DAY(EOMONTH(M$5,0)),0) -> 1 | N7: =IF($H7=1,MAX(0,MIN($G7,EOMONTH(N$5,0))-MAX($F7,N$5)+1)/DAY(EOMONTH(N$5,0)),0) -> 1 | O7: =IF($H7=1,MAX(0,MIN($G7,EOMONTH(O$5,0))-MAX($F7,O$5)+1)/DAY(EOMONTH(O$5,0)),0) -> 1 | P7: =IF($H7=1,MAX(0,MIN($G7,EOMONTH(P$5,0))-MAX($F7,P$5)+1)/DAY(EOMONTH(P$5,0)),0) -> 1 | Q7: =IF($H7=1,MAX(0,MIN($G7,EOMONTH(Q$5,0))-MAX($F7,Q$5)+1)/DAY(EOMONTH(Q$5,0)),0) -> 1 | R7: =IF($H7=1,MAX(0,MIN($G7,EOMONTH(R$5,0))-MAX($F7,R$5)+1)/DAY(EOMONTH(R$5,0)),0) -> 1 | ... V7: =IF($H7=1,MAX(0,MIN($G7,EOMONTH(V$5,0))-MAX($F7,V$5)+1)/DAY(EOMONTH(V$5,0)),0) -> 1 | W7: =$E7/12*K7*IF(AND($J7=1,W$5>=Assumptions!$B$18),1+Assumptions!$B$17,1) -> 6750 | X7: =$E7/12*L7*IF(AND($J7=1,X$5>=Assumptions!$B$18),1+Assumptions!$B$17,1) -> 6750 | Y7: =$E7/12*M7*IF(AND($J7=1,Y$5>=Assumptions!$B$18),1+Assumptions!$B$17,1) -> 6750 | Z7: =$E7/12*N7*IF(AND($J7=1,Z$5>=Assumptions!$B$18),1+Assumptions!$B$17,1) -> 6986.25 | AA7: =$E7/12*O7*IF(AND($J7=1,AA$5>=Assumptions!$B$18),1+Assumptions!$B$17,1) -> 6986.25 | AB7: =$E7/12*P7*IF(AND($J7=1,AB$5>=Assumptions!$B$18),1+Assumptions!$B$17,1) -> 6986.25 | AC7: =$E7/12*Q7*IF(AND($J7=1,AC$5>=Assumptions!$B$18),1+Assumptions!$B$17,1) -> 6986.25 | AD7: =$E7/12*R7*IF(AND($J7=1,AD$5>=Assumptions!$B$18),1+Assumptions!$B$17,1) -> 6986.25 | ... AH7: =$E7/12*V7*IF(AND($J7=1,AH$5>=Assumptions!$B$18),1+Assumptions!$B$17,1) -> 6986.25
A8: =Roster!A8 -> ENG-103 | B8: =Roster!B8 -> Engineering | C8: =Roster!E8 -> Existing | D8: =Roster!D8 -> 1 | E8: =Roster!F8 -> 86000 | F8: =IF(Roster!E8="Open role",MAX(Assumptions!$B$14,EDATE(Roster!G8,IF(Roster!I8=2,Assumptions!$F$10,0)-Assumptions!$F$9)),Roster!G8) -> 43922 | G8: =IF(Roster!H8="",DATE(2099,12,31),Roster!H8) -> 73050 | H8: =IF(Roster!E8="Existing",1,IF(Roster!I8<=Assumptions!$F$8,1,0)) -> 1 | I8: =IF(B8="Sales",Assumptions!$B$23,VLOOKUP(D8,Assumptions!$A$27:$B$31,2,FALSE())) -> 0.05 | J8: =IF(F8<Assumptions!$B$14,1,0) -> 1 | K8: =IF($H8=1,MAX(0,MIN($G8,EOMONTH(K$5,0))-MAX($F8,K$5)+1)/DAY(EOMONTH(K$5,0)),0) -> 1 | L8: =IF($H8=1,MAX(0,MIN($G8,EOMONTH(L$5,0))-MAX($F8,L$5)+1)/DAY(EOMONTH(L$5,0)),0) -> 1 | M8: =IF($H8=1,MAX(0,MIN($G8,EOMONTH(M$5,0))-MAX($F8,M$5)+1)/DAY(EOMONTH(M$5,0)),0) -> 1 | N8: =IF($H8=1,MAX(0,MIN($G8,EOMONTH(N$5,0))-MAX($F8,N$5)+1)/DAY(EOMONTH(N$5,0)),0) -> 1 | O8: =IF($H8=1,MAX(0,MIN($G8,EOMONTH(O$5,0))-MAX($F8,O$5)+1)/DAY(EOMONTH(O$5,0)),0) -> 1 | P8: =IF($H8=1,MAX(0,MIN($G8,EOMONTH(P$5,0))-MAX($F8,P$5)+1)/DAY(EOMONTH(P$5,0)),0) -> 1 | Q8: =IF($H8=1,MAX(0,MIN($G8,EOMONTH(Q$5,0))-MAX($F8,Q$5)+1)/DAY(EOMONTH(Q$5,0)),0) -> 1 | R8: =IF($H8=1,MAX(0,MIN($G8,EOMONTH(R$5,0))-MAX($F8,R$5)+1)/DAY(EOMONTH(R$5,0)),0) -> 1 | ... V8: =IF($H8=1,MAX(0,MIN($G8,EOMONTH(V$5,0))-MAX($F8,V$5)+1)/DAY(EOMONTH(V$5,0)),0) -> 1 | W8: =$E8/12*K8*IF(AND($J8=1,W$5>=Assumptions!$B$18),1+Assumptions!$B$17,1) -> 7166.6667 | X8: =$E8/12*L8*IF(AND($J8=1,X$5>=Assumptions!$B$18),1+Assumptions!$B$17,1) -> 7166.6667 | Y8: =$E8/12*M8*IF(AND($J8=1,Y$5>=Assumptions!$B$18),1+Assumptions!$B$17,1) -> 7166.6667 | Z8: =$E8/12*N8*IF(AND($J8=1,Z$5>=Assumptions!$B$18),1+Assumptions!$B$17,1) -> 7417.5 | AA8: =$E8/12*O8*IF(AND($J8=1,AA$5>=Assumptions!$B$18),1+Assumptions!$B$17,1) -> 7417.5 | AB8: =$E8/12*P8*IF(AND($J8=1,AB$5>=Assumptions!$B$18),1+Assumptions!$B$17,1) -> 7417.5 | AC8: =$E8/12*Q8*IF(AND($J8=1,AC$5>=Assumptions!$B$18),1+Assumptions!$B$17,1) -> 7417.5 | AD8: =$E8/12*R8*IF(AND($J8=1,AD$5>=Assumptions!$B$18),1+Assumptions!$B$17,1) -> 7417.5 | ... AH8: =$E8/12*V8*IF(AND($J8=1,AH$5>=Assumptions!$B$18),1+Assumptions!$B$17,1) -> 7417.5
A9: =Roster!A9 -> ENG-104 | B9: =Roster!B9 -> Engineering | C9: =Roster!E9 -> Existing | D9: =Roster!D9 -> 1 | E9: =Roster!F9 -> 79500 | F9: =IF(Roster!E9="Open role",MAX(Assumptions!$B$14,EDATE(Roster!G9,IF(Roster!I9=2,Assumptions!$F$10,0)-Assumptions!$F$9)),Roster!G9) -> 45170 | G9: =IF(Roster!H9="",DATE(2099,12,31),Roster!H9) -> 73050 | H9: =IF(Roster!E9="Existing",1,IF(Roster!I9<=Assumptions!$F$8,1,0)) -> 1 | I9: =IF(B9="Sales",Assumptions!$B$23,VLOOKUP(D9,Assumptions!$A$27:$B$31,2,FALSE())) -> 0.05 | J9: =IF(F9<Assumptions!$B$14,1,0) -> 1 | K9: =IF($H9=1,MAX(0,MIN($G9,EOMONTH(K$5,0))-MAX($F9,K$5)+1)/DAY(EOMONTH(K$5,0)),0) -> 1 | L9: =IF($H9=1,MAX(0,MIN($G9,EOMONTH(L$5,0))-MAX($F9,L$5)+1)/DAY(EOMONTH(L$5,0)),0) -> 1 | M9: =IF($H9=1,MAX(0,MIN($G9,EOMONTH(M$5,0))-MAX($F9,M$5)+1)/DAY(EOMONTH(M$5,0)),0) -> 1 | N9: =IF($H9=1,MAX(0,MIN($G9,EOMONTH(N$5,0))-MAX($F9,N$5)+1)/DAY(EOMONTH(N$5,0)),0) -> 1 | O9: =IF($H9=1,MAX(0,MIN($G9,EOMONTH(O$5,0))-MAX($F9,O$5)+1)/DAY(EOMONTH(O$5,0)),0) -> 1 | P9: =IF($H9=1,MAX(0,MIN($G9,EOMONTH(P$5,0))-MAX($F9,P$5)+1)/DAY(EOMONTH(P$5,0)),0) -> 1 | Q9: =IF($H9=1,MAX(0,MIN($G9,EOMONTH(Q$5,0))-MAX($F9,Q$5)+1)/DAY(EOMONTH(Q$5,0)),0) -> 1 | R9: =IF($H9=1,MAX(0,MIN($G9,EOMONTH(R$5,0))-MAX($F9,R$5)+1)/DAY(EOMONTH(R$5,0)),0) -> 1 | ... V9: =IF($H9=1,MAX(0,MIN($G9,EOMONTH(V$5,0))-MAX($F9,V$5)+1)/DAY(EOMONTH(V$5,0)),0) -> 1 | W9: =$E9/12*K9*IF(AND($J9=1,W$5>=Assumptions!$B$18),1+Assumptions!$B$17,1) -> 6625 | X9: =$E9/12*L9*IF(AND($J9=1,X$5>=Assumptions!$B$18),1+Assumptions!$B$17,1) -> 6625 | Y9: =$E9/12*M9*IF(AND($J9=1,Y$5>=Assumptions!$B$18),1+Assumptions!$B$17,1) -> 6625 | Z9: =$E9/12*N9*IF(AND($J9=1,Z$5>=Assumptions!$B$18),1+Assumptions!$B$17,1) -> 6856.875 | AA9: =$E9/12*O9*IF(AND($J9=1,AA$5>=Assumptions!$B$18),1+Assumptions!$B$17,1) -> 6856.875 | AB9: =$E9/12*P9*IF(AND($J9=1,AB$5>=Assumptions!$B$18),1+Assumptions!$B$17,1) -> 6856.875 | AC9: =$E9/12*Q9*IF(AND($J9=1,AC$5>=Assumptions!$B$18),1+Assumptions!$B$17,1) -> 6856.875 | AD9: =$E9/12*R9*IF(AND($J9=1,AD$5>=Assumptions!$B$18),1+Assumptions!$B$17,1) -> 6856.875 | ... AH9: =$E9/12*V9*IF(AND($J9=1,AH$5>=Assumptions!$B$18),1+Assumptions!$B$17,1) -> 6856.875
A10: =Roster!A10 -> ENG-105 | B10: =Roster!B10 -> Engineering | C10: =Roster!E10 -> Existing | D10: =Roster!D10 -> 2 | E10: =Roster!F10 -> 110500 | F10: =IF(Roster!E10="Open role",MAX(Assumptions!$B$14,EDATE(Roster!G10,IF(Roster!I10=2,Assumptions!$F$10,0)-Assumptions!$F$9)),Roster!G10) -> 46054 | G10: =IF(Roster!H10="",DATE(2099,12,31),Roster!H10) -> 73050 | H10: =IF(Roster!E10="Existing",1,IF(Roster!I10<=Assumptions!$F$8,1,0)) -> 1 | I10: =IF(B10="Sales",Assumptions!$B$23,VLOOKUP(D10,Assumptions!$A$27:$B$31,2,FALSE())) -> 0.08 | J10: =IF(F10<Assumptions!$B$14,1,0) -> 1 | K10: =IF($H10=1,MAX(0,MIN($G10,EOMONTH(K$5,0))-MAX($F10,K$5)+1)/DAY(EOMONTH(K$5,0)),0) -> 1 | L10: =IF($H10=1,MAX(0,MIN($G10,EOMONTH(L$5,0))-MAX($F10,L$5)+1)/DAY(EOMONTH(L$5,0)),0) -> 1 | M10: =IF($H10=1,MAX(0,MIN($G10,EOMONTH(M$5,0))-MAX($F10,M$5)+1)/DAY(EOMONTH(M$5,0)),0) -> 1 | N10: =IF($H10=1,MAX(0,MIN($G10,EOMONTH(N$5,0))-MAX($F10,N$5)+1)/DAY(EOMONTH(N$5,0)),0) -> 1 | O10: =IF($H10=1,MAX(0,MIN($G10,EOMONTH(O$5,0))-MAX($F10,O$5)+1)/DAY(EOMONTH(O$5,0)),0) -> 1 | P10: =IF($H10=1,MAX(0,MIN($G10,EOMONTH(P$5,0))-MAX($F10,P$5)+1)/DAY(EOMONTH(P$5,0)),0) -> 1 | Q10: =IF($H10=1,MAX(0,MIN($G10,EOMONTH(Q$5,0))-MAX($F10,Q$5)+1)/DAY(EOMONTH(Q$5,0)),0) -> 1 | R10: =IF($H10=1,MAX(0,MIN($G10,EOMONTH(R$5,0))-MAX($F10,R$5)+1)/DAY(EOMONTH(R$5,0)),0) -> 1 | ... V10: =IF($H10=1,MAX(0,MIN($G10,EOMONTH(V$5,0))-MAX($F10,V$5)+1)/DAY(EOMONTH(V$5,0)),0) -> 1 | W10: =$E10/12*K10*IF(AND($J10=1,W$5>=Assumptions!$B$18),1+Assumptions!$B$17,1) -> 9208.3333 | X10: =$E10/12*L10*IF(AND($J10=1,X$5>=Assumptions!$B$18),1+Assumptions!$B$17,1) -> 9208.3333 | Y10: =$E10/12*M10*IF(AND($J10=1,Y$5>=Assumptions!$B$18),1+Assumptions!$B$17,1) -> 9208.3333 | Z10: =$E10/12*N10*IF(AND($J10=1,Z$5>=Assumptions!$B$18),1+Assumptions!$B$17,1) -> 9530.625 | AA10: =$E10/12*O10*IF(AND($J10=1,AA$5>=Assumptions!$B$18),1+Assumptions!$B$17,1) -> 9530.625 | AB10: =$E10/12*P10*IF(AND($J10=1,AB$5>=Assumptions!$B$18),1+Assumptions!$B$17,1) -> 9530.625 | AC10: =$E10/12*Q10*IF(AND($J10=1,AC$5>=Assumptions!$B$18),1+Assumptions!$B$17,1) -> 9530.625 | AD10: =$E10/12*R10*IF(AND($J10=1,AD$5>=Assumptions!$B$18),1+Assumptions!$B$17,1) -> 9530.625 | ... AH10: =$E10/12*V10*IF(AND($J10=1,AH$5>=Assumptions!$B$18),1+Assumptions!$B$17,1) -> 9530.625
A11: =Roster!A11 -> ENG-106 | B11: =Roster!B11 -> Engineering | C11: =Roster!E11 -> Existing | D11: =Roster!D11 -> 2 | E11: =Roster!F11 -> 108000 | F11: =IF(Roster!E11="Open role",MAX(Assumptions!$B$14,EDATE(Roster!G11,IF(Roster!I11=2,Assumptions!$F$10,0)-Assumptions!$F$9)),Roster!G11) -> 44378 | G11: =IF(Roster!H11="",DATE(2099,12,31),Roster!H11) -> 73050 | H11: =IF(Roster!E11="Existing",1,IF(Roster!I11<=Assumptions!$F$8,1,0)) -> 1 | I11: =IF(B11="Sales",Assumptions!$B$23,VLOOKUP(D11,Assumptions!$A$27:$B$31,2,FALSE())) -> 0.08 | J11: =IF(F11<Assumptions!$B$14,1,0) -> 1 | K11: =IF($H11=1,MAX(0,MIN($G11,EOMONTH(K$5,0))-MAX($F11,K$5)+1)/DAY(EOMONTH(K$5,0)),0) -> 1 | L11: =IF($H11=1,MAX(0,MIN($G11,EOMONTH(L$5,0))-MAX($F11,L$5)+1)/DAY(EOMONTH(L$5,0)),0) -> 1 | M11: =IF($H11=1,MAX(0,MIN($G11,EOMONTH(M$5,0))-MAX($F11,M$5)+1)/DAY(EOMONTH(M$5,0)),0) -> 1 | N11: =IF($H11=1,MAX(0,MIN($G11,EOMONTH(N$5,0))-MAX($F11,N$5)+1)/DAY(EOMONTH(N$5,0)),0) -> 1 | O11: =IF($H11=1,MAX(0,MIN($G11,EOMONTH(O$5,0))-MAX($F11,O$5)+1)/DAY(EOMONTH(O$5,0)),0) -> 1 | P11: =IF($H11=1,MAX(0,MIN($G11,EOMONTH(P$5,0))-MAX($F11,P$5)+1)/DAY(EOMONTH(P$5,0)),0) -> 1 | Q11: =IF($H11=1,MAX(0,MIN($G11,EOMONTH(Q$5,0))-MAX($F11,Q$5)+1)/DAY(EOMONTH(Q$5,0)),0) -> 1 | R11: =IF($H11=1,MAX(0,MIN($G11,EOMONTH(R$5,0))-MAX($F11,R$5)+1)/DAY(EOMONTH(R$5,0)),0) -> 1 | ... V11: =IF($H11=1,MAX(0,MIN($G11,EOMONTH(V$5,0))-MAX($F11,V$5)+1)/DAY(EOMONTH(V$5,0)),0) -> 1 | W11: =$E11/12*K11*IF(AND($J11=1,W$5>=Assumptions!$B$18),1+Assumptions!$B$17,1) -> 9000 | X11: =$E11/12*L11*IF(AND($J11=1,X$5>=Assumptions!$B$18),1+Assumptions!$B$17,1) -> 9000 | Y11: =$E11/12*M11*IF(AND($J11=1,Y$5>=Assumptions!$B$18),1+Assumptions!$B$17,1) -> 9000 | Z11: =$E11/12*N11*IF(AND($J11=1,Z$5>=Assumptions!$B$18),1+Assumptions!$B$17,1) -> 9315 | AA11: =$E11/12*O11*IF(AND($J11=1,AA$5>=Assumptions!$B$18),1+Assumptions!$B$17,1) -> 9315 | AB11: =$E11/12*P11*IF(AND($J11=1,AB$5>=Assumptions!$B$18),1+Assumptions!$B$17,1) -> 9315 | AC11: =$E11/12*Q11*IF(AND($J11=1,AC$5>=Assumptions!$B$18),1+Assumptions!$B$17,1) -> 9315 | AD11: =$E11/12*R11*IF(AND($J11=1,AD$5>=Assumptions!$B$18),1+Assumptions!$B$17,1) -> 9315 | ... AH11: =$E11/12*V11*IF(AND($J11=1,AH$5>=Assumptions!$B$18),1+Assumptions!$B$17,1) -> 9315
A12: =Roster!A12 -> ENG-107 | B12: =Roster!B12 -> Engineering | C12: =Roster!E12 -> Existing | D12: =Roster!D12 -> 2 | E12: =Roster!F12 -> 112500 | F12: =IF(Roster!E12="Open role",MAX(Assumptions!$B$14,EDATE(Roster!G12,IF(Roster!I12=2,Assumptions!$F$10,0)-Assumptions!$F$9)),Roster!G12) -> 45627 | G12: =IF(Roster!H12="",DATE(2099,12,31),Roster!H12) -> 73050 | H12: =IF(Roster!E12="Existing",1,IF(Roster!I12<=Assumptions!$F$8,1,0)) -> 1 | I12: =IF(B12="Sales",Assumptions!$B$23,VLOOKUP(D12,Assumptions!$A$27:$B$31,2,FALSE())) -> 0.08 | J12: =IF(F12<Assumptions!$B$14,1,0) -> 1 | K12: =IF($H12=1,MAX(0,MIN($G12,EOMONTH(K$5,0))-MAX($F12,K$5)+1)/DAY(EOMONTH(K$5,0)),0) -> 1 | L12: =IF($H12=1,MAX(0,MIN($G12,EOMONTH(L$5,0))-MAX($F12,L$5)+1)/DAY(EOMONTH(L$5,0)),0) -> 1 | M12: =IF($H12=1,MAX(0,MIN($G12,EOMONTH(M$5,0))-MAX($F12,M$5)+1)/DAY(EOMONTH(M$5,0)),0) -> 1 | N12: =IF($H12=1,MAX(0,MIN($G12,EOMONTH(N$5,0))-MAX($F12,N$5)+1)/DAY(EOMONTH(N$5,0)),0) -> 1 | O12: =IF($H12=1,MAX(0,MIN($G12,EOMONTH(O$5,0))-MAX($F12,O$5)+1)/DAY(EOMONTH(O$5,0)),0) -> 1 | P12: =IF($H12=1,MAX(0,MIN($G12,EOMONTH(P$5,0))-MAX($F12,P$5)+1)/DAY(EOMONTH(P$5,0)),0) -> 1 | Q12: =IF($H12=1,MAX(0,MIN($G12,EOMONTH(Q$5,0))-MAX($F12,Q$5)+1)/DAY(EOMONTH(Q$5,0)),0) -> 1 | R12: =IF($H12=1,MAX(0,MIN($G12,EOMONTH(R$5,0))-MAX($F12,R$5)+1)/DAY(EOMONTH(R$5,0)),0) -> 1 | ... V12: =IF($H12=1,MAX(0,MIN($G12,EOMONTH(V$5,0))-MAX($F12,V$5)+1)/DAY(EOMONTH(V$5,0)),0) -> 1 | W12: =$E12/12*K12*IF(AND($J12=1,W$5>=Assumptions!$B$18),1+Assumptions!$B$17,1) -> 9375 | X12: =$E12/12*L12*IF(AND($J12=1,X$5>=Assumptions!$B$18),1+Assumptions!$B$17,1) -> 9375 | Y12: =$E12/12*M12*IF(AND($J12=1,Y$5>=Assumptions!$B$18),1+Assumptions!$B$17,1) -> 9375 | Z12: =$E12/12*N12*IF(AND($J12=1,Z$5>=Assumptions!$B$18),1+Assumptions!$B$17,1) -> 9703.125 | AA12: =$E12/12*O12*IF(AND($J12=1,AA$5>=Assumptions!$B$18),1+Assumptions!$B$17,1) -> 9703.125 | AB12: =$E12/12*P12*IF(AND($J12=1,AB$5>=Assumptions!$B$18),1+Assumptions!$B$17,1) -> 9703.125 | AC12: =$E12/12*Q12*IF(AND($J12=1,AC$5>=Assumptions!$B$18),1+Assumptions!$B$17,1) -> 9703.125 | AD12: =$E12/12*R12*IF(AND($J12=1,AD$5>=Assumptions!$B$18),1+Assumptions!$B$17,1) -> 9703.125 | ... AH12: =$E12/12*V12*IF(AND($J12=1,AH$5>=Assumptions!$B$18),1+Assumptions!$B$17,1) -> 9703.125
A13: =Roster!A13 -> ENG-108 | B13: =Roster!B13 -> Engineering | C13: =Roster!E13 -> Existing | D13: =Roster!D13 -> 2 | E13: =Roster!F13 -> 109000 | F13: =IF(Roster!E13="Open role",MAX(Assumptions!$B$14,EDATE(Roster!G13,IF(Roster!I13=2,Assumptions!$F$10,0)-Assumptions!$F$9)),Roster!G13) -> 43586 | G13: =IF(Roster!H13="",DATE(2099,12,31),Roster!H13) -> 73050 | H13: =IF(Roster!E13="Existing",1,IF(Roster!I13<=Assumptions!$F$8,1,0)) -> 1 | I13: =IF(B13="Sales",Assumptions!$B$23,VLOOKUP(D13,Assumptions!$A$27:$B$31,2,FALSE())) -> 0.08 | J13: =IF(F13<Assumptions!$B$14,1,0) -> 1 | K13: =IF($H13=1,MAX(0,MIN($G13,EOMONTH(K$5,0))-MAX($F13,K$5)+1)/DAY(EOMONTH(K$5,0)),0) -> 1 | L13: =IF($H13=1,MAX(0,MIN($G13,EOMONTH(L$5,0))-MAX($F13,L$5)+1)/DAY(EOMONTH(L$5,0)),0) -> 1 | M13: =IF($H13=1,MAX(0,MIN($G13,EOMONTH(M$5,0))-MAX($F13,M$5)+1)/DAY(EOMONTH(M$5,0)),0) -> 1 | N13: =IF($H13=1,MAX(0,MIN($G13,EOMONTH(N$5,0))-MAX($F13,N$5)+1)/DAY(EOMONTH(N$5,0)),0) -> 1 | O13: =IF($H13=1,MAX(0,MIN($G13,EOMONTH(O$5,0))-MAX($F13,O$5)+1)/DAY(EOMONTH(O$5,0)),0) -> 1 | P13: =IF($H13=1,MAX(0,MIN($G13,EOMONTH(P$5,0))-MAX($F13,P$5)+1)/DAY(EOMONTH(P$5,0)),0) -> 1 | Q13: =IF($H13=1,MAX(0,MIN($G13,EOMONTH(Q$5,0))-MAX($F13,Q$5)+1)/DAY(EOMONTH(Q$5,0)),0) -> 1 | R13: =IF($H13=1,MAX(0,MIN($G13,EOMONTH(R$5,0))-MAX($F13,R$5)+1)/DAY(EOMONTH(R$5,0)),0) -> 1 | ... V13: =IF($H13=1,MAX(0,MIN($G13,EOMONTH(V$5,0))-MAX($F13,V$5)+1)/DAY(EOMONTH(V$5,0)),0) -> 1 | W13: =$E13/12*K13*IF(AND($J13=1,W$5>=Assumptions!$B$18),1+Assumptions!$B$17,1) -> 9083.3333 | X13: =$E13/12*L13*IF(AND($J13=1,X$5>=Assumptions!$B$18),1+Assumptions!$B$17,1) -> 9083.3333 | Y13: =$E13/12*M13*IF(AND($J13=1,Y$5>=Assumptions!$B$18),1+Assumptions!$B$17,1) -> 9083.3333 | Z13: =$E13/12*N13*IF(AND($J13=1,Z$5>=Assumptions!$B$18),1+Assumptions!$B$17,1) -> 9401.25 | AA13: =$E13/12*O13*IF(AND($J13=1,AA$5>=Assumptions!$B$18),1+Assumptions!$B$17,1) -> 9401.25 | AB13: =$E13/12*P13*IF(AND($J13=1,AB$5>=Assumptions!$B$18),1+Assumptions!$B$17,1) -> 9401.25 | AC13: =$E13/12*Q13*IF(AND($J13=1,AC$5>=Assumptions!$B$18),1+Assumptions!$B$17,1) -> 9401.25 | AD13: =$E13/12*R13*IF(AND($J13=1,AD$5>=Assumptions!$B$18),1+Assumptions!$B$17,1) -> 9401.25 | ... AH13: =$E13/12*V13*IF(AND($J13=1,AH$5>=Assumptions!$B$18),1+Assumptions!$B$17,1) -> 9401.25
A14: =Roster!A14 -> ENG-109 | B14: =Roster!B14 -> Engineering | C14: =Roster!E14 -> Existing | D14: =Roster!D14 -> 2 | E14: =Roster!F14 -> 111500 | F14: =IF(Roster!E14="Open role",MAX(Assumptions!$B$14,EDATE(Roster!G14,IF(Roster!I14=2,Assumptions!$F$10,0)-Assumptions!$F$9)),Roster!G14) -> 44835 | G14: =IF(Roster!H14="",DATE(2099,12,31),Roster!H14) -> 73050 | H14: =IF(Roster!E14="Existing",1,IF(Roster!I14<=Assumptions!$F$8,1,0)) -> 1 | I14: =IF(B14="Sales",Assumptions!$B$23,VLOOKUP(D14,Assumptions!$A$27:$B$31,2,FALSE())) -> 0.08 | J14: =IF(F14<Assumptions!$B$14,1,0) -> 1 | K14: =IF($H14=1,MAX(0,MIN($G14,EOMONTH(K$5,0))-MAX($F14,K$5)+1)/DAY(EOMONTH(K$5,0)),0) -> 1 | L14: =IF($H14=1,MAX(0,MIN($G14,EOMONTH(L$5,0))-MAX($F14,L$5)+1)/DAY(EOMONTH(L$5,0)),0) -> 1 | M14: =IF($H14=1,MAX(0,MIN($G14,EOMONTH(M$5,0))-MAX($F14,M$5)+1)/DAY(EOMONTH(M$5,0)),0) -> 1 | N14: =IF($H14=1,MAX(0,MIN($G14,EOMONTH(N$5,0))-MAX($F14,N$5)+1)/DAY(EOMONTH(N$5,0)),0) -> 1 | O14: =IF($H14=1,MAX(0,MIN($G14,EOMONTH(O$5,0))-MAX($F14,O$5)+1)/DAY(EOMONTH(O$5,0)),0) -> 1 | P14: =IF($H14=1,MAX(0,MIN($G14,EOMONTH(P$5,0))-MAX($F14,P$5)+1)/DAY(EOMONTH(P$5,0)),0) -> 1 | Q14: =IF($H14=1,MAX(0,MIN($G14,EOMONTH(Q$5,0))-MAX($F14,Q$5)+1)/DAY(EOMONTH(Q$5,0)),0) -> 1 | R14: =IF($H14=1,MAX(0,MIN($G14,EOMONTH(R$5,0))-MAX($F14,R$5)+1)/DAY(EOMONTH(R$5,0)),0) -> 1 | ... V14: =IF($H14=1,MAX(0,MIN($G14,EOMONTH(V$5,0))-MAX($F14,V$5)+1)/DAY(EOMONTH(V$5,0)),0) -> 1 | W14: =$E14/12*K14*IF(AND($J14=1,W$5>=Assumptions!$B$18),1+Assumptions!$B$17,1) -> 9291.6667 | X14: =$E14/12*L14*IF(AND($J14=1,X$5>=Assumptions!$B$18),1+Assumptions!$B$17,1) -> 9291.6667 | Y14: =$E14/12*M14*IF(AND($J14=1,Y$5>=Assumptions!$B$18),1+Assumptions!$B$17,1) -> 9291.6667 | Z14: =$E14/12*N14*IF(AND($J14=1,Z$5>=Assumptions!$B$18),1+Assumptions!$B$17,1) -> 9616.875 | AA14: =$E14/12*O14*IF(AND($J14=1,AA$5>=Assumptions!$B$18),1+Assumptions!$B$17,1) -> 9616.875 | AB14: =$E14/12*P14*IF(AND($J14=1,AB$5>=Assumptions!$B$18),1+Assumptions!$B$17,1) -> 9616.875 | AC14: =$E14/12*Q14*IF(AND($J14=1,AC$5>=Assumptions!$B$18),1+Assumptions!$B$17,1) -> 9616.875 | AD14: =$E14/12*R14*IF(AND($J14=1,AD$5>=Assumptions!$B$18),1+Assumptions!$B$17,1) -> 9616.875 | ... AH14: =$E14/12*V14*IF(AND($J14=1,AH$5>=Assumptions!$B$18),1+Assumptions!$B$17,1) -> 9616.875
A15: =Roster!A15 -> ENG-110 | B15: =Roster!B15 -> Engineering | C15: =Roster!E15 -> Existing | D15: =Roster!D15 -> 2 | E15: =Roster!F15 -> 107000 | F15: =IF(Roster!E15="Open role",MAX(Assumptions!$B$14,EDATE(Roster!G15,IF(Roster!I15=2,Assumptions!$F$10,0)-Assumptions!$F$9)),Roster!G15) -> 45717 | G15: =IF(Roster!H15="",DATE(2099,12,31),Roster!H15) -> 73050 | H15: =IF(Roster!E15="Existing",1,IF(Roster!I15<=Assumptions!$F$8,1,0)) -> 1 | I15: =IF(B15="Sales",Assumptions!$B$23,VLOOKUP(D15,Assumptions!$A$27:$B$31,2,FALSE())) -> 0.08 | J15: =IF(F15<Assumptions!$B$14,1,0) -> 1 | K15: =IF($H15=1,MAX(0,MIN($G15,EOMONTH(K$5,0))-MAX($F15,K$5)+1)/DAY(EOMONTH(K$5,0)),0) -> 1 | L15: =IF($H15=1,MAX(0,MIN($G15,EOMONTH(L$5,0))-MAX($F15,L$5)+1)/DAY(EOMONTH(L$5,0)),0) -> 1 | M15: =IF($H15=1,MAX(0,MIN($G15,EOMONTH(M$5,0))-MAX($F15,M$5)+1)/DAY(EOMONTH(M$5,0)),0) -> 1 | N15: =IF($H15=1,MAX(0,MIN($G15,EOMONTH(N$5,0))-MAX($F15,N$5)+1)/DAY(EOMONTH(N$5,0)),0) -> 1 | O15: =IF($H15=1,MAX(0,MIN($G15,EOMONTH(O$5,0))-MAX($F15,O$5)+1)/DAY(EOMONTH(O$5,0)),0) -> 1 | P15: =IF($H15=1,MAX(0,MIN($G15,EOMONTH(P$5,0))-MAX($F15,P$5)+1)/DAY(EOMONTH(P$5,0)),0) -> 1 | Q15: =IF($H15=1,MAX(0,MIN($G15,EOMONTH(Q$5,0))-MAX($F15,Q$5)+1)/DAY(EOMONTH(Q$5,0)),0) -> 1 | R15: =IF($H15=1,MAX(0,MIN($G15,EOMONTH(R$5,0))-MAX($F15,R$5)+1)/DAY(EOMONTH(R$5,0)),0) -> 1 | ... V15: =IF($H15=1,MAX(0,MIN($G15,EOMONTH(V$5,0))-MAX($F15,V$5)+1)/DAY(EOMONTH(V$5,0)),0) -> 1 | W15: =$E15/12*K15*IF(AND($J15=1,W$5>=Assumptions!$B$18),1+Assumptions!$B$17,1) -> 8916.6667 | X15: =$E15/12*L15*IF(AND($J15=1,X$5>=Assumptions!$B$18),1+Assumptions!$B$17,1) -> 8916.6667 | Y15: =$E15/12*M15*IF(AND($J15=1,Y$5>=Assumptions!$B$18),1+Assumptions!$B$17,1) -> 8916.6667 | Z15: =$E15/12*N15*IF(AND($J15=1,Z$5>=Assumptions!$B$18),1+Assumptions!$B$17,1) -> 9228.75 | AA15: =$E15/12*O15*IF(AND($J15=1,AA$5>=Assumptions!$B$18),1+Assumptions!$B$17,1) -> 9228.75 | AB15: =$E15/12*P15*IF(AND($J15=1,AB$5>=Assumptions!$B$18),1+Assumptions!$B$17,1) -> 9228.75 | AC15: =$E15/12*Q15*IF(AND($J15=1,AC$5>=Assumptions!$B$18),1+Assumptions!$B$17,1) -> 9228.75 | AD15: =$E15/12*R15*IF(AND($J15=1,AD$5>=Assumptions!$B$18),1+Assumptions!$B$17,1) -> 9228.75 | ... AH15: =$E15/12*V15*IF(AND($J15=1,AH$5>=Assumptions!$B$18),1+Assumptions!$B$17,1) -> 9228.75
A16: =Roster!A16 -> ENG-111 | B16: =Roster!B16 -> Engineering | C16: =Roster!E16 -> Existing | D16: =Roster!D16 -> 3 | E16: =Roster!F16 -> 153000 | F16: =IF(Roster!E16="Open role",MAX(Assumptions!$B$14,EDATE(Roster!G16,IF(Roster!I16=2,Assumptions!$F$10,0)-Assumptions!$F$9)),Roster!G16) -> 44044 | G16: =IF(Roster!H16="",DATE(2099,12,31),Roster!H16) -> 46507 | H16: =IF(Roster!E16="Existing",1,IF(Roster!I16<=Assumptions!$F$8,1,0)) -> 1 | I16: =IF(B16="Sales",Assumptions!$B$23,VLOOKUP(D16,Assumptions!$A$27:$B$31,2,FALSE())) -> 0.1 | J16: =IF(F16<Assumptions!$B$14,1,0) -> 1 | K16: =IF($H16=1,MAX(0,MIN($G16,EOMONTH(K$5,0))-MAX($F16,K$5)+1)/DAY(EOMONTH(K$5,0)),0) -> 1 | L16: =IF($H16=1,MAX(0,MIN($G16,EOMONTH(L$5,0))-MAX($F16,L$5)+1)/DAY(EOMONTH(L$5,0)),0) -> 1 | M16: =IF($H16=1,MAX(0,MIN($G16,EOMONTH(M$5,0))-MAX($F16,M$5)+1)/DAY(EOMONTH(M$5,0)),0) -> 1 | N16: =IF($H16=1,MAX(0,MIN($G16,EOMONTH(N$5,0))-MAX($F16,N$5)+1)/DAY(EOMONTH(N$5,0)),0) -> 1 | O16: =IF($H16=1,MAX(0,MIN($G16,EOMONTH(O$5,0))-MAX($F16,O$5)+1)/DAY(EOMONTH(O$5,0)),0) -> 0 | P16: =IF($H16=1,MAX(0,MIN($G16,EOMONTH(P$5,0))-MAX($F16,P$5)+1)/DAY(EOMONTH(P$5,0)),0) -> 0 | Q16: =IF($H16=1,MAX(0,MIN($G16,EOMONTH(Q$5,0))-MAX($F16,Q$5)+1)/DAY(EOMONTH(Q$5,0)),0) -> 0 | R16: =IF($H16=1,MAX(0,MIN($G16,EOMONTH(R$5,0))-MAX($F16,R$5)+1)/DAY(EOMONTH(R$5,0)),0) -> 0 | ... V16: =IF($H16=1,MAX(0,MIN($G16,EOMONTH(V$5,0))-MAX($F16,V$5)+1)/DAY(EOMONTH(V$5,0)),0) -> 0 | W16: =$E16/12*K16*IF(AND($J16=1,W$5>=Assumptions!$B$18),1+Assumptions!$B$17,1) -> 12750 | X16: =$E16/12*L16*IF(AND($J16=1,X$5>=Assumptions!$B$18),1+Assumptions!$B$17,1) -> 12750 | Y16: =$E16/12*M16*IF(AND($J16=1,Y$5>=Assumptions!$B$18),1+Assumptions!$B$17,1) -> 12750 | Z16: =$E16/12*N16*IF(AND($J16=1,Z$5>=Assumptions!$B$18),1+Assumptions!$B$17,1) -> 13196.25 | AA16: =$E16/12*O16*IF(AND($J16=1,AA$5>=Assumptions!$B$18),1+Assumptions!$B$17,1) -> 0 | AB16: =$E16/12*P16*IF(AND($J16=1,AB$5>=Assumptions!$B$18),1+Assumptions!$B$17,1) -> 0 | AC16: =$E16/12*Q16*IF(AND($J16=1,AC$5>=Assumptions!$B$18),1+Assumptions!$B$17,1) -> 0 | AD16: =$E16/12*R16*IF(AND($J16=1,AD$5>=Assumptions!$B$18),1+Assumptions!$B$17,1) -> 0 | ... AH16: =$E16/12*V16*IF(AND($J16=1,AH$5>=Assumptions!$B$18),1+Assumptions!$B$17,1) -> 0
A17: =Roster!A17 -> ENG-112 | B17: =Roster!B17 -> Engineering | C17: =Roster!E17 -> Existing | D17: =Roster!D17 -> 3 | E17: =Roster!F17 -> 141500 | F17: =IF(Roster!E17="Open role",MAX(Assumptions!$B$14,EDATE(Roster!G17,IF(Roster!I17=2,Assumptions!$F$10,0)-Assumptions!$F$9)),Roster!G17) -> 44927 | G17: =IF(Roster!H17="",DATE(2099,12,31),Roster!H17) -> 73050 | H17: =IF(Roster!E17="Existing",1,IF(Roster!I17<=Assumptions!$F$8,1,0)) -> 1 | I17: =IF(B17="Sales",Assumptions!$B$23,VLOOKUP(D17,Assumptions!$A$27:$B$31,2,FALSE())) -> 0.1 | J17: =IF(F17<Assumptions!$B$14,1,0) -> 1 | K17: =IF($H17=1,MAX(0,MIN($G17,EOMONTH(K$5,0))-MAX($F17,K$5)+1)/DAY(EOMONTH(K$5,0)),0) -> 1 | L17: =IF($H17=1,MAX(0,MIN($G17,EOMONTH(L$5,0))-MAX($F17,L$5)+1)/DAY(EOMONTH(L$5,0)),0) -> 1 | M17: =IF($H17=1,MAX(0,MIN($G17,EOMONTH(M$5,0))-MAX($F17,M$5)+1)/DAY(EOMONTH(M$5,0)),0) -> 1 | N17: =IF($H17=1,MAX(0,MIN($G17,EOMONTH(N$5,0))-MAX($F17,N$5)+1)/DAY(EOMONTH(N$5,0)),0) -> 1 | O17: =IF($H17=1,MAX(0,MIN($G17,EOMONTH(O$5,0))-MAX($F17,O$5)+1)/DAY(EOMONTH(O$5,0)),0) -> 1 | P17: =IF($H17=1,MAX(0,MIN($G17,EOMONTH(P$5,0))-MAX($F17,P$5)+1)/DAY(EOMONTH(P$5,0)),0) -> 1 | Q17: =IF($H17=1,MAX(0,MIN($G17,EOMONTH(Q$5,0))-MAX($F17,Q$5)+1)/DAY(EOMONTH(Q$5,0)),0) -> 1 | R17: =IF($H17=1,MAX(0,MIN($G17,EOMONTH(R$5,0))-MAX($F17,R$5)+1)/DAY(EOMONTH(R$5,0)),0) -> 1 | ... V17: =IF($H17=1,MAX(0,MIN($G17,EOMONTH(V$5,0))-MAX($F17,V$5)+1)/DAY(EOMONTH(V$5,0)),0) -> 1 | W17: =$E17/12*K17*IF(AND($J17=1,W$5>=Assumptions!$B$18),1+Assumptions!$B$17,1) -> 11791.667 | X17: =$E17/12*L17*IF(AND($J17=1,X$5>=Assumptions!$B$18),1+Assumptions!$B$17,1) -> 11791.667 | Y17: =$E17/12*M17*IF(AND($J17=1,Y$5>=Assumptions!$B$18),1+Assumptions!$B$17,1) -> 11791.667 | Z17: =$E17/12*N17*IF(AND($J17=1,Z$5>=Assumptions!$B$18),1+Assumptions!$B$17,1) -> 12204.375 | AA17: =$E17/12*O17*IF(AND($J17=1,AA$5>=Assumptions!$B$18),1+Assumptions!$B$17,1) -> 12204.375 | AB17: =$E17/12*P17*IF(AND($J17=1,AB$5>=Assumptions!$B$18),1+Assumptions!$B$17,1) -> 12204.375 | AC17: =$E17/12*Q17*IF(AND($J17=1,AC$5>=Assumptions!$B$18),1+Assumptions!$B$17,1) -> 12204.375 | AD17: =$E17/12*R17*IF(AND($J17=1,AD$5>=Assumptions!$B$18),1+Assumptions!$B$17,1) -> 12204.375 | ... AH17: =$E17/12*V17*IF(AND($J17=1,AH$5>=Assumptions!$B$18),1+Assumptions!$B$17,1) -> 12204.375
... A83: =Roster!A83 -> TBH-GNA-02 | B83: =Roster!B83 -> G&A | C83: =Roster!E83 -> Open role | D83: =Roster!D83 -> 2 | E83: =Roster!F83 -> 93000 | F83: =IF(Roster!E83="Open role",MAX(Assumptions!$B$14,EDATE(Roster!G83,IF(Roster!I83=2,Assumptions!$F$10,0)-Assumptions!$F$9)),Roster!G83) -> 46539 | G83: =IF(Roster!H83="",DATE(2099,12,31),Roster!H83) -> 73050 | H83: =IF(Roster!E83="Existing",1,IF(Roster!I83<=Assumptions!$F$8,1,0)) -> 1 | I83: =IF(B83="Sales",Assumptions!$B$23,VLOOKUP(D83,Assumptions!$A$27:$B$31,2,FALSE())) -> 0.08 | J83: =IF(F83<Assumptions!$B$14,1,0) -> 0 | K83: =IF($H83=1,MAX(0,MIN($G83,EOMONTH(K$5,0))-MAX($F83,K$5)+1)/DAY(EOMONTH(K$5,0)),0) -> 0 | L83: =IF($H83=1,MAX(0,MIN($G83,EOMONTH(L$5,0))-MAX($F83,L$5)+1)/DAY(EOMONTH(L$5,0)),0) -> 0 | M83: =IF($H83=1,MAX(0,MIN($G83,EOMONTH(M$5,0))-MAX($F83,M$5)+1)/DAY(EOMONTH(M$5,0)),0) -> 0 | N83: =IF($H83=1,MAX(0,MIN($G83,EOMONTH(N$5,0))-MAX($F83,N$5)+1)/DAY(EOMONTH(N$5,0)),0) -> 0 | O83: =IF($H83=1,MAX(0,MIN($G83,EOMONTH(O$5,0))-MAX($F83,O$5)+1)/DAY(EOMONTH(O$5,0)),0) -> 0 | P83: =IF($H83=1,MAX(0,MIN($G83,EOMONTH(P$5,0))-MAX($F83,P$5)+1)/DAY(EOMONTH(P$5,0)),0) -> 1 | Q83: =IF($H83=1,MAX(0,MIN($G83,EOMONTH(Q$5,0))-MAX($F83,Q$5)+1)/DAY(EOMONTH(Q$5,0)),0) -> 1 | R83: =IF($H83=1,MAX(0,MIN($G83,EOMONTH(R$5,0))-MAX($F83,R$5)+1)/DAY(EOMONTH(R$5,0)),0) -> 1 | ... V83: =IF($H83=1,MAX(0,MIN($G83,EOMONTH(V$5,0))-MAX($F83,V$5)+1)/DAY(EOMONTH(V$5,0)),0) -> 1 | W83: =$E83/12*K83*IF(AND($J83=1,W$5>=Assumptions!$B$18),1+Assumptions!$B$17,1) -> 0 | X83: =$E83/12*L83*IF(AND($J83=1,X$5>=Assumptions!$B$18),1+Assumptions!$B$17,1) -> 0 | Y83: =$E83/12*M83*IF(AND($J83=1,Y$5>=Assumptions!$B$18),1+Assumptions!$B$17,1) -> 0 | Z83: =$E83/12*N83*IF(AND($J83=1,Z$5>=Assumptions!$B$18),1+Assumptions!$B$17,1) -> 0 | AA83: =$E83/12*O83*IF(AND($J83=1,AA$5>=Assumptions!$B$18),1+Assumptions!$B$17,1) -> 0 | AB83: =$E83/12*P83*IF(AND($J83=1,AB$5>=Assumptions!$B$18),1+Assumptions!$B$17,1) -> 7750 | AC83: =$E83/12*Q83*IF(AND($J83=1,AC$5>=Assumptions!$B$18),1+Assumptions!$B$17,1) -> 7750 | AD83: =$E83/12*R83*IF(AND($J83=1,AD$5>=Assumptions!$B$18),1+Assumptions!$B$17,1) -> 7750 | ... AH83: =$E83/12*V83*IF(AND($J83=1,AH$5>=Assumptions!$B$18),1+Assumptions!$B$17,1) -> 7750
A84: Total | K84: =SUM(K6:K83) -> 60 | L84: =SUM(L6:L83) -> 62 | M84: =SUM(M6:M83) -> 64 | N84: =SUM(N6:N83) -> 66 | O84: =SUM(O6:O83) -> 67 | P84: =SUM(P6:P83) -> 70 | Q84: =SUM(Q6:Q83) -> 71 | R84: =SUM(R6:R83) -> 71 | ... AH84: =SUM(AH6:AH83) -> 697945.83

Sheet Department Budget
A1: FY2027 Operating Expense Budget by Department ($)
A2: ="Scenario: "&Assumptions!$C$5&" | Monthly budget, January–December 2027" -> Scenario: Plan | Monthly budget, January–December 2027
A4: Line item | B4: ='Headcount Calc'!K5 -> 46388 | C4: ='Headcount Calc'!L5 -> 46419 | D4: ='Headcount Calc'!M5 -> 46447 | E4: ='Headcount Calc'!N5 -> 46478 | F4: ='Headcount Calc'!O5 -> 46508 | G4: ='Headcount Calc'!P5 -> 46539 | H4: ='Headcount Calc'!Q5 -> 46569 | I4: ='Headcount Calc'!R5 -> 46600 | ... M4: ='Headcount Calc'!V5 -> 46722 | N4: FY2027
A6: Engineering
A7: FTE (average for the month) | B7: =SUMIF('Headcount Calc'!$B$6:$B$83,$A$6,'Headcount Calc'!K$6:K$83) -> 20 | C7: =SUMIF('Headcount Calc'!$B$6:$B$83,$A$6,'Headcount Calc'!L$6:L$83) -> 21 | D7: =SUMIF('Headcount Calc'!$B$6:$B$83,$A$6,'Headcount Calc'!M$6:M$83) -> 21 | E7: =SUMIF('Headcount Calc'!$B$6:$B$83,$A$6,'Headcount Calc'!N$6:N$83) -> 22 | F7: =SUMIF('Headcount Calc'!$B$6:$B$83,$A$6,'Headcount Calc'!O$6:O$83) -> 22 | G7: =SUMIF('Headcount Calc'!$B$6:$B$83,$A$6,'Headcount Calc'!P$6:P$83) -> 23 | H7: =SUMIF('Headcount Calc'!$B$6:$B$83,$A$6,'Headcount Calc'!Q$6:Q$83) -> 24 | I7: =SUMIF('Headcount Calc'!$B$6:$B$83,$A$6,'Headcount Calc'!R$6:R$83) -> 24 | ... M7: =SUMIF('Headcount Calc'!$B$6:$B$83,$A$6,'Headcount Calc'!V$6:V$83) -> 24 | N7: =AVERAGE(B7:M7) -> 22.75
A8: Salaries | B8: =SUMIF('Headcount Calc'!$B$6:$B$83,$A$6,'Headcount Calc'!W$6:W$83) -> 224708.33 | C8: =SUMIF('Headcount Calc'!$B$6:$B$83,$A$6,'Headcount Calc'!X$6:X$83) -> 233708.33 | D8: =SUMIF('Headcount Calc'!$B$6:$B$83,$A$6,'Headcount Calc'!Y$6:Y$83) -> 233708.33 | E8: =SUMIF('Headcount Calc'!$B$6:$B$83,$A$6,'Headcount Calc'!Z$6:Z$83) -> 250656.46 | F8: =SUMIF('Headcount Calc'!$B$6:$B$83,$A$6,'Headcount Calc'!AA$6:AA$83) -> 250085.21 | G8: =SUMIF('Headcount Calc'!$B$6:$B$83,$A$6,'Headcount Calc'!AB$6:AB$83) -> 262585.21 | H8: =SUMIF('Headcount Calc'!$B$6:$B$83,$A$6,'Headcount Calc'!AC$6:AC$83) -> 278085.21 | I8: =SUMIF('Headcount Calc'!$B$6:$B$83,$A$6,'Headcount Calc'!AD$6:AD$83) -> 278085.21 | ... M8: =SUMIF('Headcount Calc'!$B$6:$B$83,$A$6,'Headcount Calc'!AH$6:AH$83) -> 278085.21 | N8: =SUM(B8:M8) -> 3123963.1
A9: Bonus & variable compensation | B9: =SUMPRODUCT(('Headcount Calc'!$B$6:$B$83=$A$6)*'Headcount Calc'!W$6:W$83*'Headcount Calc'!$I$6:$I$83) -> 24423.333 | C9: =SUMPRODUCT(('Headcount Calc'!$B$6:$B$83=$A$6)*'Headcount Calc'!X$6:X$83*'Headcount Calc'!$I$6:$I$83) -> 25143.333 | D9: =SUMPRODUCT(('Headcount Calc'!$B$6:$B$83=$A$6)*'Headcount Calc'!Y$6:Y$83*'Headcount Calc'!$I$6:$I$83) -> 25143.333 | E9: =SUMPRODUCT(('Headcount Calc'!$B$6:$B$83=$A$6)*'Headcount Calc'!Z$6:Z$83*'Headcount Calc'!$I$6:$I$83) -> 26724.817 | F9: =SUMPRODUCT(('Headcount Calc'!$B$6:$B$83=$A$6)*'Headcount Calc'!AA$6:AA$83*'Headcount Calc'!$I$6:$I$83) -> 26667.692 | G9: =SUMPRODUCT(('Headcount Calc'!$B$6:$B$83=$A$6)*'Headcount Calc'!AB$6:AB$83*'Headcount Calc'!$I$6:$I$83) -> 27917.692 | H9: =SUMPRODUCT(('Headcount Calc'!$B$6:$B$83=$A$6)*'Headcount Calc'!AC$6:AC$83*'Headcount Calc'!$I$6:$I$83) -> 30242.692 | I9: =SUMPRODUCT(('Headcount Calc'!$B$6:$B$83=$A$6)*'Headcount Calc'!AD$6:AD$83*'Headcount Calc'!$I$6:$I$83) -> 30242.692 | ... M9: =SUMPRODUCT(('Headcount Calc'!$B$6:$B$83=$A$6)*'Headcount Calc'!AH$6:AH$83*'Headcount Calc'!$I$6:$I$83) -> 30242.692 | N9: =SUM(B9:M9) -> 337476.35
A10: Payroll taxes | B10: =(B8+B9)*Assumptions!$B$15 -> 17937.48 | C10: =(C8+C9)*Assumptions!$B$15 -> 18637.32 | D10: =(D8+D9)*Assumptions!$B$15 -> 18637.32 | E10: =(E8+E9)*Assumptions!$B$15 -> 19971.452 | F10: =(F8+F9)*Assumptions!$B$15 -> 19926.209 | G10: =(G8+G9)*Assumptions!$B$15 -> 20916.209 | H10: =(H8+H9)*Assumptions!$B$15 -> 22199.609 | I10: =(I8+I9)*Assumptions!$B$15 -> 22199.609 | ... M10: =(M8+M9)*Assumptions!$B$15 -> 22199.609 | N10: =SUM(B10:M10) -> 249223.64
A11: Benefits | B11: =B7*Assumptions!$B$16 -> 23000 | C11: =C7*Assumptions!$B$16 -> 24150 | D11: =D7*Assumptions!$B$16 -> 24150 | E11: =E7*Assumptions!$B$16 -> 25300 | F11: =F7*Assumptions!$B$16 -> 25300 | G11: =G7*Assumptions!$B$16 -> 26450 | H11: =H7*Assumptions!$B$16 -> 27600 | I11: =I7*Assumptions!$B$16 -> 27600 | ... M11: =M7*Assumptions!$B$16 -> 27600 | N11: =SUM(B11:M11) -> 313950
A12: Recruiting & onboarding | B12: =SUMPRODUCT(('Headcount Calc'!$B$6:$B$83=$A$6)*('Headcount Calc'!$C$6:$C$83="Open role")*('Headcount Calc'!$H$6:$H$83=1)*('Headcount Calc'!$F$6:$F$83>=B$4)*('Headcount Calc'!$F$6:$F$83<=EOMONTH(B$4,0))*'Headcount Calc'!$E$6:$E$83)*Assumptions!$B$19+SUMPRODUCT(('Headcount Calc'!$B$6:$B$83=$A$6)*('Headcount Calc'!$C$6:$C$83="Open role")*('Headcount Calc'!$H$6:$H$83=1)*('Headcount Calc'!$F$6:$F$83>=B$4)*('Headcount Calc'!$F$6:$F$83<=EOMONTH(B$4,0)))*Assumptions!$B$20 -> 0 | C12: =SUMPRODUCT(('Headcount Calc'!$B$6:$B$83=$A$6)*('Headcount Calc'!$C$6:$C$83="Open role")*('Headcount Calc'!$H$6:$H$83=1)*('Headcount Calc'!$F$6:$F$83>=C$4)*('Headcount Calc'!$F$6:$F$83<=EOMONTH(C$4,0))*'Headcount Calc'!$E$6:$E$83)*Assumptions!$B$19+SUMPRODUCT(('Headcount Calc'!$B$6:$B$83=$A$6)*('Headcount Calc'!$C$6:$C$83="Open role")*('Headcount Calc'!$H$6:$H$83=1)*('Headcount Calc'!$F$6:$F$83>=C$4)*('Headcount Calc'!$F$6:$F$83<=EOMONTH(C$4,0)))*Assumptions!$B$20 -> 19200 | D12: =SUMPRODUCT(('Headcount Calc'!$B$6:$B$83=$A$6)*('Headcount Calc'!$C$6:$C$83="Open role")*('Headcount Calc'!$H$6:$H$83=1)*('Headcount Calc'!$F$6:$F$83>=D$4)*('Headcount Calc'!$F$6:$F$83<=EOMONTH(D$4,0))*'Headcount Calc'!$E$6:$E$83)*Assumptions!$B$19+SUMPRODUCT(('Headcount Calc'!$B$6:$B$83=$A$6)*('Headcount Calc'!$C$6:$C$83="Open role")*('Headcount Calc'!$H$6:$H$83=1)*('Headcount Calc'!$F$6:$F$83>=D$4)*('Headcount Calc'!$F$6:$F$83<=EOMONTH(D$4,0)))*Assumptions!$B$20 -> 0 | E12: =SUMPRODUCT(('Headcount Calc'!$B$6:$B$83=$A$6)*('Headcount Calc'!$C$6:$C$83="Open role")*('Headcount Calc'!$H$6:$H$83=1)*('Headcount Calc'!$F$6:$F$83>=E$4)*('Headcount Calc'!$F$6:$F$83<=EOMONTH(E$4,0))*'Headcount Calc'!$E$6:$E$83)*Assumptions!$B$19+SUMPRODUCT(('Headcount Calc'!$B$6:$B$83=$A$6)*('Headcount Calc'!$C$6:$C$83="Open role")*('Headcount Calc'!$H$6:$H$83=1)*('Headcount Calc'!$F$6:$F$83>=E$4)*('Headcount Calc'!$F$6:$F$83<=EOMONTH(E$4,0)))*Assumptions!$B$20 -> 19350 | F12: =SUMPRODUCT(('Headcount Calc'!$B$6:$B$83=$A$6)*('Headcount Calc'!$C$6:$C$83="Open role")*('Headcount Calc'!$H$6:$H$83=1)*('Headcount Calc'!$F$6:$F$83>=F$4)*('Headcount Calc'!$F$6:$F$83<=EOMONTH(F$4,0))*'Headcount Calc'!$E$6:$E$83)*Assumptions!$B$19+SUMPRODUCT(('Headcount Calc'!$B$6:$B$83=$A$6)*('Headcount Calc'!$C$6:$C$83="Open role")*('Headcount Calc'!$H$6:$H$83=1)*('Headcount Calc'!$F$6:$F$83>=F$4)*('Headcount Calc'!$F$6:$F$83<=EOMONTH(F$4,0)))*Assumptions!$B$20 -> 25725 | G12: =SUMPRODUCT(('Headcount Calc'!$B$6:$B$83=$A$6)*('Headcount Calc'!$C$6:$C$83="Open role")*('Headcount Calc'!$H$6:$H$83=1)*('Headcount Calc'!$F$6:$F$83>=G$4)*('Headcount Calc'!$F$6:$F$83<=EOMONTH(G$4,0))*'Headcount Calc'!$E$6:$E$83)*Assumptions!$B$19+SUMPRODUCT(('Headcount Calc'!$B$6:$B$83=$A$6)*('Headcount Calc'!$C$6:$C$83="Open role")*('Headcount Calc'!$H$6:$H$83=1)*('Headcount Calc'!$F$6:$F$83>=G$4)*('Headcount Calc'!$F$6:$F$83<=EOMONTH(G$4,0)))*Assumptions!$B$20 -> 25500 | H12: =SUMPRODUCT(('Headcount Calc'!$B$6:$B$83=$A$6)*('Headcount Calc'!$C$6:$C$83="Open role")*('Headcount Calc'!$H$6:$H$83=1)*('Headcount Calc'!$F$6:$F$83>=H$4)*('Headcount Calc'!$F$6:$F$83<=EOMONTH(H$4,0))*'Headcount Calc'!$E$6:$E$83)*Assumptions!$B$19+SUMPRODUCT(('Headcount Calc'!$B$6:$B$83=$A$6)*('Headcount Calc'!$C$6:$C$83="Open role")*('Headcount Calc'!$H$6:$H$83=1)*('Headcount Calc'!$F$6:$F$83>=H$4)*('Headcount Calc'!$F$6:$F$83<=EOMONTH(H$4,0)))*Assumptions!$B$20 -> 30900 | I12: =SUMPRODUCT(('Headcount Calc'!$B$6:$B$83=$A$6)*('Headcount Calc'!$C$6:$C$83="Open role")*('Headcount Calc'!$H$6:$H$83=1)*('Headcount Calc'!$F$6:$F$83>=I$4)*('Headcount Calc'!$F$6:$F$83<=EOMONTH(I$4,0))*'Headcount Calc'!$E$6:$E$83)*Assumptions!$B$19+SUMPRODUCT(('Headcount Calc'!$B$6:$B$83=$A$6)*('Headcount Calc'!$C$6:$C$83="Open role")*('Headcount Calc'!$H$6:$H$83=1)*('Headcount Calc'!$F$6:$F$83>=I$4)*('Headcount Calc'!$F$6:$F$83<=EOMONTH(I$4,0)))*Assumptions!$B$20 -> 0 | ... M12: =SUMPRODUCT(('Headcount Calc'!$B$6:$B$83=$A$6)*('Headcount Calc'!$C$6:$C$83="Open role")*('Headcount Calc'!$H$6:$H$83=1)*('Headcount Calc'!$F$6:$F$83>=M$4)*('Headcount Calc'!$F$6:$F$83<=EOMONTH(M$4,0))*'Headcount Calc'!$E$6:$E$83)*Assumptions!$B$19+SUMPRODUCT(('Headcount Calc'!$B$6:$B$83=$A$6)*('Headcount Calc'!$C$6:$C$83="Open role")*('Headcount Calc'!$H$6:$H$83=1)*('Headcount Calc'!$F$6:$F$83>=M$4)*('Headcount Calc'!$F$6:$F$83<=EOMONTH(M$4,0)))*Assumptions!$B$20 -> 0 | N12: =SUM(B12:M12) -> 120675
A13: Software & tools | B13: =B7*Assumptions!$B$21 -> 5000 | C13: =C7*Assumptions!$B$21 -> 5250 | D13: =D7*Assumptions!$B$21 -> 5250 | E13: =E7*Assumptions!$B$21 -> 5500 | F13: =F7*Assumptions!$B$21 -> 5500 | G13: =G7*Assumptions!$B$21 -> 5750 | H13: =H7*Assumptions!$B$21 -> 6000 | I13: =I7*Assumptions!$B$21 -> 6000 | ... M13: =M7*Assumptions!$B$21 -> 6000 | N13: =SUM(B13:M13) -> 68250
A14: Travel & entertainment | B14: =B7*VLOOKUP($A$6,Assumptions!$A$35:$C$40,2,FALSE()) -> 3000 | C14: =C7*VLOOKUP($A$6,Assumptions!$A$35:$C$40,2,FALSE()) -> 3150 | D14: =D7*VLOOKUP($A$6,Assumptions!$A$35:$C$40,2,FALSE()) -> 3150 | E14: =E7*VLOOKUP($A$6,Assumptions!$A$35:$C$40,2,FALSE()) -> 3300 | F14: =F7*VLOOKUP($A$6,Assumptions!$A$35:$C$40,2,FALSE()) -> 3300 | G14: =G7*VLOOKUP($A$6,Assumptions!$A$35:$C$40,2,FALSE()) -> 3450 | H14: =H7*VLOOKUP($A$6,Assumptions!$A$35:$C$40,2,FALSE()) -> 3600 | I14: =I7*VLOOKUP($A$6,Assumptions!$A$35:$C$40,2,FALSE()) -> 3600 | ... M14: =M7*VLOOKUP($A$6,Assumptions!$A$35:$C$40,2,FALSE()) -> 3600 | N14: =SUM(B14:M14) -> 40950
A15: Facilities | B15: =B7*Assumptions!$B$22 -> 12000 | C15: =C7*Assumptions!$B$22 -> 12600 | D15: =D7*Assumptions!$B$22 -> 12600 | E15: =E7*Assumptions!$B$22 -> 13200 | F15: =F7*Assumptions!$B$22 -> 13200 | G15: =G7*Assumptions!$B$22 -> 13800 | H15: =H7*Assumptions!$B$22 -> 14400 | I15: =I7*Assumptions!$B$22 -> 14400 | ... M15: =M7*Assumptions!$B$22 -> 14400 | N15: =SUM(B15:M15) -> 163800
A16: Programs & vendors | B16: =VLOOKUP($A$6,Assumptions!$A$35:$C$40,3,FALSE())/12*(1+Assumptions!$F$11) -> 50000 | C16: =VLOOKUP($A$6,Assumptions!$A$35:$C$40,3,FALSE())/12*(1+Assumptions!$F$11) -> 50000 | D16: =VLOOKUP($A$6,Assumptions!$A$35:$C$40,3,FALSE())/12*(1+Assumptions!$F$11) -> 50000 | E16: =VLOOKUP($A$6,Assumptions!$A$35:$C$40,3,FALSE())/12*(1+Assumptions!$F$11) -> 50000 | F16: =VLOOKUP($A$6,Assumptions!$A$35:$C$40,3,FALSE())/12*(1+Assumptions!$F$11) -> 50000 | G16: =VLOOKUP($A$6,Assumptions!$A$35:$C$40,3,FALSE())/12*(1+Assumptions!$F$11) -> 50000 | H16: =VLOOKUP($A$6,Assumptions!$A$35:$C$40,3,FALSE())/12*(1+Assumptions!$F$11) -> 50000 | I16: =VLOOKUP($A$6,Assumptions!$A$35:$C$40,3,FALSE())/12*(1+Assumptions!$F$11) -> 50000 | ... M16: =VLOOKUP($A$6,Assumptions!$A$35:$C$40,3,FALSE())/12*(1+Assumptions!$F$11) -> 50000 | N16: =SUM(B16:M16) -> 600000
A17: Total operating expense | B17: =SUM(B8:B16) -> 360069.15 | C17: =SUM(C8:C16) -> 391838.99 | D17: =SUM(D8:D16) -> 372638.99 | E17: =SUM(E8:E16) -> 414002.73 | F17: =SUM(F8:F16) -> 419704.11 | G17: =SUM(G8:G16) -> 436369.11 | H17: =SUM(H8:H16) -> 463027.51 | I17: =SUM(I8:I16) -> 432127.51 | ... M17: =SUM(M8:M16) -> 432127.51 | N17: =SUM(B17:M17) -> 5018288.1
A19: Product
A20: FTE (average for the month) | B20: =SUMIF('Headcount Calc'!$B$6:$B$83,$A$19,'Headcount Calc'!K$6:K$83) -> 5 | C20: =SUMIF('Headcount Calc'!$B$6:$B$83,$A$19,'Headcount Calc'!L$6:L$83) -> 5 | D20: =SUMIF('Headcount Calc'!$B$6:$B$83,$A$19,'Headcount Calc'!M$6:M$83) -> 6 | E20: =SUMIF('Headcount Calc'!$B$6:$B$83,$A$19,'Headcount Calc'!N$6:N$83) -> 6 | F20: =SUMIF('Headcount Calc'!$B$6:$B$83,$A$19,'Headcount Calc'!O$6:O$83) -> 6 | G20: =SUMIF('Headcount Calc'!$B$6:$B$83,$A$19,'Headcount Calc'!P$6:P$83) -> 6 | H20: =SUMIF('Headcount Calc'!$B$6:$B$83,$A$19,'Headcount Calc'!Q$6:Q$83) -> 6 | I20: =SUMIF('Headcount Calc'!$B$6:$B$83,$A$19,'Headcount Calc'!R$6:R$83) -> 6 | ... M20: =SUMIF('Headcount Calc'!$B$6:$B$83,$A$19,'Headcount Calc'!V$6:V$83) -> 6 | N20: =AVERAGE(B20:M20) -> 5.8333333
A21: Salaries | B21: =SUMIF('Headcount Calc'!$B$6:$B$83,$A$19,'Headcount Calc'!W$6:W$83) -> 61041.667 | C21: =SUMIF('Headcount Calc'!$B$6:$B$83,$A$19,'Headcount Calc'!X$6:X$83) -> 61041.667 | D21: =SUMIF('Headcount Calc'!$B$6:$B$83,$A$19,'Headcount Calc'!Y$6:Y$83) -> 72666.667 | E21: =SUMIF('Headcount Calc'!$B$6:$B$83,$A$19,'Headcount Calc'!Z$6:Z$83) -> 74803.125 | F21: =SUMIF('Headcount Calc'!$B$6:$B$83,$A$19,'Headcount Calc'!AA$6:AA$83) -> 74803.125 | G21: =SUMIF('Headcount Calc'!$B$6:$B$83,$A$19,'Headcount Calc'!AB$6:AB$83) -> 74803.125 | H21: =SUMIF('Headcount Calc'!$B$6:$B$83,$A$19,'Headcount Calc'!AC$6:AC$83) -> 74803.125 | I21: =SUMIF('Headcount Calc'!$B$6:$B$83,$A$19,'Headcount Calc'!AD$6:AD$83) -> 74803.125 | ... M21: =SUMIF('Headcount Calc'!$B$6:$B$83,$A$19,'Headcount Calc'!AH$6:AH$83) -> 74803.125 | N21: =SUM(B21:M21) -> 867978.12
A22: Bonus & variable compensation | B22: =SUMPRODUCT(('Headcount Calc'!$B$6:$B$83=$A$19)*'Headcount Calc'!W$6:W$83*'Headcount Calc'!$I$6:$I$83) -> 7777.5 | C22: =SUMPRODUCT(('Headcount Calc'!$B$6:$B$83=$A$19)*'Headcount Calc'!X$6:X$83*'Headcount Calc'!$I$6:$I$83) -> 7777.5 | D22: =SUMPRODUCT(('Headcount Calc'!$B$6:$B$83=$A$19)*'Headcount Calc'!Y$6:Y$83*'Headcount Calc'!$I$6:$I$83) -> 8940 | E22: =SUMPRODUCT(('Headcount Calc'!$B$6:$B$83=$A$19)*'Headcount Calc'!Z$6:Z$83*'Headcount Calc'!$I$6:$I$83) -> 9212.2125 | F22: =SUMPRODUCT(('Headcount Calc'!$B$6:$B$83=$A$19)*'Headcount Calc'!AA$6:AA$83*'Headcount Calc'!$I$6:$I$83) -> 9212.2125 | G22: =SUMPRODUCT(('Headcount Calc'!$B$6:$B$83=$A$19)*'Headcount Calc'!AB$6:AB$83*'Headcount Calc'!$I$6:$I$83) -> 9212.2125 | H22: =SUMPRODUCT(('Headcount Calc'!$B$6:$B$83=$A$19)*'Headcount Calc'!AC$6:AC$83*'Headcount Calc'!$I$6:$I$83) -> 9212.2125 | I22: =SUMPRODUCT(('Headcount Calc'!$B$6:$B$83=$A$19)*'Headcount Calc'!AD$6:AD$83*'Headcount Calc'!$I$6:$I$83) -> 9212.2125 | ... M22: =SUMPRODUCT(('Headcount Calc'!$B$6:$B$83=$A$19)*'Headcount Calc'!AH$6:AH$83*'Headcount Calc'!$I$6:$I$83) -> 9212.2125 | N22: =SUM(B22:M22) -> 107404.91
A23: Payroll taxes | B23: =(B21+B22)*Assumptions!$B$15 -> 4954.98 | C23: =(C21+C22)*Assumptions!$B$15 -> 4954.98 | D23: =(D21+D22)*Assumptions!$B$15 -> 5875.68 | E23: =(E21+E22)*Assumptions!$B$15 -> 6049.1043 | F23: =(F21+F22)*Assumptions!$B$15 -> 6049.1043 | G23: =(G21+G22)*Assumptions!$B$15 -> 6049.1043 | H23: =(H21+H22)*Assumptions!$B$15 -> 6049.1043 | I23: =(I21+I22)*Assumptions!$B$15 -> 6049.1043 | ... M23: =(M21+M22)*Assumptions!$B$15 -> 6049.1043 | N23: =SUM(B23:M23) -> 70227.579
A24: Benefits | B24: =B20*Assumptions!$B$16 -> 5750 | C24: =C20*Assumptions!$B$16 -> 5750 | D24: =D20*Assumptions!$B$16 -> 6900 | E24: =E20*Assumptions!$B$16 -> 6900 | F24: =F20*Assumptions!$B$16 -> 6900 | G24: =G20*Assumptions!$B$16 -> 6900 | H24: =H20*Assumptions!$B$16 -> 6900 | I24: =I20*Assumptions!$B$16 -> 6900 | ... M24: =M20*Assumptions!$B$16 -> 6900 | N24: =SUM(B24:M24) -> 80500
A25: Recruiting & onboarding | B25: =SUMPRODUCT(('Headcount Calc'!$B$6:$B$83=$A$19)*('Headcount Calc'!$C$6:$C$83="Open role")*('Headcount Calc'!$H$6:$H$83=1)*('Headcount Calc'!$F$6:$F$83>=B$4)*('Headcount Calc'!$F$6:$F$83<=EOMONTH(B$4,0))*'Headcount Calc'!$E$6:$E$83)*Assumptions!$B$19+SUMPRODUCT(('Headcount Calc'!$B$6:$B$83=$A$19)*('Headcount Calc'!$C$6:$C$83="Open role")*('Headcount Calc'!$H$6:$H$83=1)*('Headcount Calc'!$F$6:$F$83>=B$4)*('Headcount Calc'!$F$6:$F$83<=EOMONTH(B$4,0)))*Assumptions!$B$20 -> 0 | C25: =SUMPRODUCT(('Headcount Calc'!$B$6:$B$83=$A$19)*('Headcount Calc'!$C$6:$C$83="Open role")*('Headcount Calc'!$H$6:$H$83=1)*('Headcount Calc'!$F$6:$F$83>=C$4)*('Headcount Calc'!$F$6:$F$83<=EOMONTH(C$4,0))*'Headcount Calc'!$E$6:$E$83)*Assumptions!$B$19+SUMPRODUCT(('Headcount Calc'!$B$6:$B$83=$A$19)*('Headcount Calc'!$C$6:$C$83="Open role")*('Headcount Calc'!$H$6:$H$83=1)*('Headcount Calc'!$F$6:$F$83>=C$4)*('Headcount Calc'!$F$6:$F$83<=EOMONTH(C$4,0)))*Assumptions!$B$20 -> 0 | D25: =SUMPRODUCT(('Headcount Calc'!$B$6:$B$83=$A$19)*('Headcount Calc'!$C$6:$C$83="Open role")*('Headcount Calc'!$H$6:$H$83=1)*('Headcount Calc'!$F$6:$F$83>=D$4)*('Headcount Calc'!$F$6:$F$83<=EOMONTH(D$4,0))*'Headcount Calc'!$E$6:$E$83)*Assumptions!$B$19+SUMPRODUCT(('Headcount Calc'!$B$6:$B$83=$A$19)*('Headcount Calc'!$C$6:$C$83="Open role")*('Headcount Calc'!$H$6:$H$83=1)*('Headcount Calc'!$F$6:$F$83>=D$4)*('Headcount Calc'!$F$6:$F$83<=EOMONTH(D$4,0)))*Assumptions!$B$20 -> 23925 | E25: =SUMPRODUCT(('Headcount Calc'!$B$6:$B$83=$A$19)*('Headcount Calc'!$C$6:$C$83="Open role")*('Headcount Calc'!$H$6:$H$83=1)*('Headcount Calc'!$F$6:$F$83>=E$4)*('Headcount Calc'!$F$6:$F$83<=EOMONTH(E$4,0))*'Headcount Calc'!$E$6:$E$83)*Assumptions!$B$19+SUMPRODUCT(('Headcount Calc'!$B$6:$B$83=$A$19)*('Headcount Calc'!$C$6:$C$83="Open role")*('Headcount Calc'!$H$6:$H$83=1)*('Headcount Calc'!$F$6:$F$83>=E$4)*('Headcount Calc'!$F$6:$F$83<=EOMONTH(E$4,0)))*Assumptions!$B$20 -> 0 | F25: =SUMPRODUCT(('Headcount Calc'!$B$6:$B$83=$A$19)*('Headcount Calc'!$C$6:$C$83="Open role")*('Headcount Calc'!$H$6:$H$83=1)*('Headcount Calc'!$F$6:$F$83>=F$4)*('Headcount Calc'!$F$6:$F$83<=EOMONTH(F$4,0))*'Headcount Calc'!$E$6:$E$83)*Assumptions!$B$19+SUMPRODUCT(('Headcount Calc'!$B$6:$B$83=$A$19)*('Headcount Calc'!$C$6:$C$83="Open role")*('Headcount Calc'!$H$6:$H$83=1)*('Headcount Calc'!$F$6:$F$83>=F$4)*('Headcount Calc'!$F$6:$F$83<=EOMONTH(F$4,0)))*Assumptions!$B$20 -> 0 | G25: =SUMPRODUCT(('Headcount Calc'!$B$6:$B$83=$A$19)*('Headcount Calc'!$C$6:$C$83="Open role")*('Headcount Calc'!$H$6:$H$83=1)*('Headcount Calc'!$F$6:$F$83>=G$4)*('Headcount Calc'!$F$6:$F$83<=EOMONTH(G$4,0))*'Headcount Calc'!$E$6:$E$83)*Assumptions!$B$19+SUMPRODUCT(('Headcount Calc'!$B$6:$B$83=$A$19)*('Headcount Calc'!$C$6:$C$83="Open role")*('Headcount Calc'!$H$6:$H$83=1)*('Headcount Calc'!$F$6:$F$83>=G$4)*('Headcount Calc'!$F$6:$F$83<=EOMONTH(G$4,0)))*Assumptions!$B$20 -> 0 | H25: =SUMPRODUCT(('Headcount Calc'!$B$6:$B$83=$A$19)*('Headcount Calc'!$C$6:$C$83="Open role")*('Headcount Calc'!$H$6:$H$83=1)*('Headcount Calc'!$F$6:$F$83>=H$4)*('Headcount Calc'!$F$6:$F$83<=EOMONTH(H$4,0))*'Headcount Calc'!$E$6:$E$83)*Assumptions!$B$19+SUMPRODUCT(('Headcount Calc'!$B$6:$B$83=$A$19)*('Headcount Calc'!$C$6:$C$83="Open role")*('Headcount Calc'!$H$6:$H$83=1)*('Headcount Calc'!$F$6:$F$83>=H$4)*('Headcount Calc'!$F$6:$F$83<=EOMONTH(H$4,0)))*Assumptions!$B$20 -> 0 | I25: =SUMPRODUCT(('Headcount Calc'!$B$6:$B$83=$A$19)*('Headcount Calc'!$C$6:$C$83="Open role")*('Headcount Calc'!$H$6:$H$83=1)*('Headcount Calc'!$F$6:$F$83>=I$4)*('Headcount Calc'!$F$6:$F$83<=EOMONTH(I$4,0))*'Headcount Calc'!$E$6:$E$83)*Assumptions!$B$19+SUMPRODUCT(('Headcount Calc'!$B$6:$B$83=$A$19)*('Headcount Calc'!$C$6:$C$83="Open role")*('Headcount Calc'!$H$6:$H$83=1)*('Headcount Calc'!$F$6:$F$83>=I$4)*('Headcount Calc'!$F$6:$F$83<=EOMONTH(I$4,0)))*Assumptions!$B$20 -> 0 | ... M25: =SUMPRODUCT(('Headcount Calc'!$B$6:$B$83=$A$19)*('Headcount Calc'!$C$6:$C$83="Open role")*('Headcount Calc'!$H$6:$H$83=1)*('Headcount Calc'!$F$6:$F$83>=M$4)*('Headcount Calc'!$F$6:$F$83<=EOMONTH(M$4,0))*'Headcount Calc'!$E$6:$E$83)*Assumptions!$B$19+SUMPRODUCT(('Headcount Calc'!$B$6:$B$83=$A$19)*('Headcount Calc'!$C$6:$C$83="Open role")*('Headcount Calc'!$H$6:$H$83=1)*('Headcount Calc'!$F$6:$F$83>=M$4)*('Headcount Calc'!$F$6:$F$83<=EOMONTH(M$4,0)))*Assumptions!$B$20 -> 0 | N25: =SUM(B25:M25) -> 23925
